Workbook

Sheet Employee_Sales_Data
A1: 🏢 TechVista Pvt. Ltd. — Employee & Sales Dataset (Jan 2024)
A2: Practice Dataset for Excel Functions | 50 Employees | Multiple Departments & Cities
A3: Emp ID | B3: Employee Name | C3: Department | D3: City | E3: Gender | F3: Age | G3: Date of Joining | H3: Basic Salary (₹) | I3: Sales Amount (₹) | J3: Sales Target (₹) | K3: Performance Rating | L3: Status | M3: Experience (Yrs) | N3: Bonus (₹) | O3: Bonus Status | P3: Sales Status | Q3: Salary status | R3: Employee Status | S3: Age Status | T3: Grade | U3: Performance Grade | V3: Experience Status | W3: Performance | X3: Generation Group | Y3: Bonus Category
A4: E001 | B4: Aarav Sharma | C4: Sales | D4: Mumbai | E4: Male | F4: 28 | G4: 2021-03-15 | H4: 52000 | I4: 185000 | J4: 180000 | K4: Excellent | L4: Active | M4: 3 | N4: 8500 | O4: =IF(N5>0,"Bonus Received","No Bonus") -> Bonus Received | P4: =IF(Employee_Sales_Data!I4>Employee_Sales_Data!J4,"Target Achieved","Target Missed") -> Target Achieved | Q4: =IF(H4>80000,"Senoir Pay Band","Junior Pay Band") -> Junior Pay Band | R4: =IF(L4="Active","Current Employee","Ex-Employee") -> Current Employee | S4: =IF(F4>40,"Vetaran","Young Talent") -> Young Talent | T4: =IF(H4>=80000,"Grade A",IF(H4>50000,"Grade B","Grade C")) -> Grade B | U4: =IF(K4="Excellent","5",IF(K4="Good","4",IF(K4="Average","3",IF(K4="Below Avg","2","1")))) -> 5 | V4: =IF(M4<3,"Fresher",IF(M4<7,"Mid Level","Senior")) -> Mid Level | W4: =IF(Table1[[#This Row],[Sales Status]]="Target Missed","Needs Improvement",IF(AND(Table1[[#This Row],[Sales Status]]="Achieved",W5="Excellent"), "Star", "Achiever" ) ) -> Achiever | X4: =IF(F4<30,"Gen-Z",IF(F4<40,"Millennial","Gen X")) -> Gen-Z | Y4: =IF(N4=0,"No Bonus",IF(N4<=8000,"Stanadard","Premium")) -> Premium
A5: E002 | B5: Priya Mehta | C5: HR | D5: Pune | E5: Female | F5: 35 | G5: 2018-07-22 | H5: 68000 | I5: 0 | J5: 0 | K5: Good | L5: Active | M5: 7 | N5: 6800 | O5: =IF(N6>0,"Bonus Received","No Bonus") -> Bonus Received | P5: =IF(Employee_Sales_Data!I5>Employee_Sales_Data!J5,"Target Achieved","Target Missed") -> Target Missed | Q5: =IF(H5>80000,"Senoir Pay Band","Junior Pay Band") -> Junior Pay Band | R5: =IF(L5="Active","Current Employee","Ex-Employee") -> Current Employee | S5: =IF(F5>40,"Vetaran","Young Talent") -> Young Talent | T5: =IF(H5>=80000,"Grade A",IF(H5>50000,"Grade B","Grade C")) -> Grade B | U5: =IF(K5="Excellent","5",IF(K5="Good","4",IF(K5="Average","3",IF(K5="Below Avg","2","1")))) -> 4 | V5: =IF(M5<3,"Fresher",IF(M5<7,"Mid Level","Senior")) -> Senior | W5: =IF(Table1[[#This Row],[Sales Status]]="Target Missed","Needs Improvement",IF(AND(Table1[[#This Row],[Sales Status]]="Achieved",W6="Excellent"), "Star", "Achiever" ) ) -> Needs Improvement | X5: =IF(F5<30,"Gen-Z",IF(F5<40,"Millennial","Gen X")) -> Millennial | Y5: =IF(N5=0,"No Bonus",IF(N5<=8000,"Stanadard","Premium")) -> Stanadard
A6: E003 | B6: Rohan Desai | C6: IT | D6: Bangalore | E6: Male | F6: 30 | G6: 2020-01-10 | H6: 75000 | I6: 0 | J6: 0 | K6: Excellent | L6: Active | M6: 5 | N6: 9200 | O6: =IF(N7>0,"Bonus Received","No Bonus") -> Bonus Received | P6: =IF(Employee_Sales_Data!I6>Employee_Sales_Data!J6,"Target Achieved","Target Missed") -> Target Missed | Q6: =IF(H6>80000,"Senoir Pay Band","Junior Pay Band") -> Junior Pay Band | R6: =IF(L6="Active","Current Employee","Ex-Employee") -> Current Employee | S6: =IF(F6>40,"Vetaran","Young Talent") -> Young Talent | T6: =IF(H6>=80000,"Grade A",IF(H6>50000,"Grade B","Grade C")) -> Grade B | U6: =IF(K6="Excellent","5",IF(K6="Good","4",IF(K6="Average","3",IF(K6="Below Avg","2","1")))) -> 5 | V6: =IF(M6<3,"Fresher",IF(M6<7,"Mid Level","Senior")) -> Mid Level | W6: =IF(Table1[[#This Row],[Sales Status]]="Target Missed","Needs Improvement",IF(AND(Table1[[#This Row],[Sales Status]]="Achieved",W7="Excellent"), "Star", "Achiever" ) ) -> Needs Improvement | X6: =IF(F6<30,"Gen-Z",IF(F6<40,"Millennial","Gen X")) -> Millennial | Y6: =IF(N6=0,"No Bonus",IF(N6<=8000,"Stanadard","Premium")) -> Premium
A7: E004 | B7: Sneha Patil | C7: Sales | D7: Mumbai | E7: Female | F7: 26 | G7: 2022-06-01 | H7: 45000 | I7: 162000 | J7: 170000 | K7: Average | L7: Active | M7: 2 | N7: 4500 | O7: =IF(N8>0,"Bonus Received","No Bonus") -> Bonus Received | P7: =IF(Employee_Sales_Data!I7>Employee_Sales_Data!J7,"Target Achieved","Target Missed") -> Target Missed | Q7: =IF(H7>80000,"Senoir Pay Band","Junior Pay Band") -> Junior Pay Band | R7: =IF(L7="Active","Current Employee","Ex-Employee") -> Current Employee | S7: =IF(F7>40,"Vetaran","Young Talent") -> Young Talent | T7: =IF(H7>=80000,"Grade A",IF(H7>50000,"Grade B","Grade C")) -> Grade C | U7: =IF(K7="Excellent","5",IF(K7="Good","4",IF(K7="Average","3",IF(K7="Below Avg","2","1")))) -> 3 | V7: =IF(M7<3,"Fresher",IF(M7<7,"Mid Level","Senior")) -> Fresher | W7: =IF(Table1[[#This Row],[Sales Status]]="Target Missed","Needs Improvement",IF(AND(Table1[[#This Row],[Sales Status]]="Achieved",W8="Excellent"), "Star", "Achiever" ) ) -> Needs Improvement | X7: =IF(F7<30,"Gen-Z",IF(F7<40,"Millennial","Gen X")) -> Gen-Z | Y7: =IF(N7=0,"No Bonus",IF(N7<=8000,"Stanadard","Premium")) -> Stanadard
A8: E005 | B8: Vikram Nair | C8: Finance | D8: Chennai | E8: Male | F8: 42 | G8: 2015-09-12 | H8: 92000 | I8: 0 | J8: 0 | K8: Excellent | L8: Active | M8: 10 | N8: 11500 | O8: =IF(N9>0,"Bonus Received","No Bonus") -> Bonus Received | P8: =IF(Employee_Sales_Data!I8>Employee_Sales_Data!J8,"Target Achieved","Target Missed") -> Target Missed | Q8: =IF(H8>80000,"Senoir Pay Band","Junior Pay Band") -> Senoir Pay Band | R8: =IF(L8="Active","Current Employee","Ex-Employee") -> Current Employee | S8: =IF(F8>40,"Vetaran","Young Talent") -> Vetaran | T8: =IF(H8>=80000,"Grade A",IF(H8>50000,"Grade B","Grade C")) -> Grade A | U8: =IF(K8="Excellent","5",IF(K8="Good","4",IF(K8="Average","3",IF(K8="Below Avg","2","1")))) -> 5 | V8: =IF(M8<3,"Fresher",IF(M8<7,"Mid Level","Senior")) -> Senior | W8: =IF(Table1[[#This Row],[Sales Status]]="Target Missed","Needs Improvement",IF(AND(Table1[[#This Row],[Sales Status]]="Achieved",W9="Excellent"), "Star", "Achiever" ) ) -> Needs Improvement | X8: =IF(F8<30,"Gen-Z",IF(F8<40,"Millennial","Gen X")) -> Gen X | Y8: =IF(N8=0,"No Bonus",IF(N8<=8000,"Stanadard","Premium")) -> Premium
A9: E006 | B9: Ananya Iyer | C9: Sales | D9: Chennai | E9: Female | F9: 31 | G9: 2019-11-25 | H9: 58000 | I9: 210000 | J9: 200000 | K9: Excellent | L9: Active | M9: 6 | N9: 9800 | O9: =IF(N10>0,"Bonus Received","No Bonus") -> Bonus Received | P9: =IF(Employee_Sales_Data!I9>Employee_Sales_Data!J9,"Target Achieved","Target Missed") -> Target Achieved | Q9: =IF(H9>80000,"Senoir Pay Band","Junior Pay Band") -> Junior Pay Band | R9: =IF(L9="Active","Current Employee","Ex-Employee") -> Current Employee | S9: =IF(F9>40,"Vetaran","Young Talent") -> Young Talent | T9: =IF(H9>=80000,"Grade A",IF(H9>50000,"Grade B","Grade C")) -> Grade B | U9: =IF(K9="Excellent","5",IF(K9="Good","4",IF(K9="Average","3",IF(K9="Below Avg","2","1")))) -> 5 | V9: =IF(M9<3,"Fresher",IF(M9<7,"Mid Level","Senior")) -> Mid Level | W9: =IF(Table1[[#This Row],[Sales Status]]="Target Missed","Needs Improvement",IF(AND(Table1[[#This Row],[Sales Status]]="Achieved",W10="Excellent"), "Star", "Achiever" ) ) -> Achiever | X9: =IF(F9<30,"Gen-Z",IF(F9<40,"Millennial","Gen X")) -> Millennial | Y9: =IF(N9=0,"No Bonus",IF(N9<=8000,"Stanadard","Premium")) -> Premium
A10: E007 | B10: Karan Joshi | C10: IT | D10: Pune | E10: Male | F10: 27 | G10: 2022-02-14 | H10: 70000 | I10: 0 | J10: 0 | K10: Good | L10: Active | M10: 3 | N10: 7000 | O10: =IF(N11>0,"Bonus Received","No Bonus") -> No Bonus | P10: =IF(Employee_Sales_Data!I10>Employee_Sales_Data!J10,"Target Achieved","Target Missed") -> Target Missed | Q10: =IF(H10>80000,"Senoir Pay Band","Junior Pay Band") -> Junior Pay Band | R10: =IF(L10="Active","Current Employee","Ex-Employee") -> Current Employee | S10: =IF(F10>40,"Vetaran","Young Talent") -> Young Talent | T10: =IF(H10>=80000,"Grade A",IF(H10>50000,"Grade B","Grade C")) -> Grade B | U10: =IF(K10="Excellent","5",IF(K10="Good","4",IF(K10="Average","3",IF(K10="Below Avg","2","1")))) -> 4 | V10: =IF(M10<3,"Fresher",IF(M10<7,"Mid Level","Senior")) -> Mid Level | W10: =IF(Table1[[#This Row],[Sales Status]]="Target Missed","Needs Improvement",IF(AND(Table1[[#This Row],[Sales Status]]="Achieved",W11="Excellent"), "Star", "Achiever" ) ) -> Needs Improvement | X10: =IF(F10<30,"Gen-Z",IF(F10<40,"Millennial","Gen X")) -> Gen-Z | Y10: =IF(N10=0,"No Bonus",IF(N10<=8000,"Stanadard","Premium")) -> Stanadard
A11: E008 | B11: Divya Reddy | C11: HR | D11: Hyderabad | E11: Female | F11: 38 | G11: 2017-04-30 | H11: 72000 | I11: 0 | J11: 0 | K11: Average | L11: Inactive | M11: 8 | N11: 0 | O11: =IF(N12>0,"Bonus Received","No Bonus") -> Bonus Received | P11: =IF(Employee_Sales_Data!I11>Employee_Sales_Data!J11,"Target Achieved","Target Missed") -> Target Missed | Q11: =IF(H11>80000,"Senoir Pay Band","Junior Pay Band") -> Junior Pay Band | R11: =IF(L11="Active","Current Employee","Ex-Employee") -> Ex-Employee | S11: =IF(F11>40,"Vetaran","Young Talent") -> Young Talent | T11: =IF(H11>=80000,"Grade A",IF(H11>50000,"Grade B","Grade C")) -> Grade B | U11: =IF(K11="Excellent","5",IF(K11="Good","4",IF(K11="Average","3",IF(K11="Below Avg","2","1")))) -> 3 | V11: =IF(M11<3,"Fresher",IF(M11<7,"Mid Level","Senior")) -> Senior | W11: =IF(Table1[[#This Row],[Sales Status]]="Target Missed","Needs Improvement",IF(AND(Table1[[#This Row],[Sales Status]]="Achieved",W12="Excellent"), "Star", "Achiever" ) ) -> Needs Improvement | X11: =IF(F11<30,"Gen-Z",IF(F11<40,"Millennial","Gen X")) -> Millennial | Y11: =IF(N11=0,"No Bonus",IF(N11<=8000,"Stanadard","Premium")) -> No Bonus
A12: E009 | B12: Aditya Kumar | C12: Sales | D12: Delhi | E12: Male | F12: 33 | G12: 2018-08-19 | H12: 61000 | I12: 195000 | J12: 190000 | K12: Good | L12: Active | M12: 7 | N12: 8200 | O12: =IF(N13>0,"Bonus Received","No Bonus") -> Bonus Received | P12: =IF(Employee_Sales_Data!I12>Employee_Sales_Data!J12,"Target Achieved","Target Missed") -> Target Achieved | Q12: =IF(H12>80000,"Senoir Pay Band","Junior Pay Band") -> Junior Pay Band | R12: =IF(L12="Active","Current Employee","Ex-Employee") -> Current Employee | S12: =IF(F12>40,"Vetaran","Young Talent") -> Young Talent | T12: =IF(H12>=80000,"Grade A",IF(H12>50000,"Grade B","Grade C")) -> Grade B | U12: =IF(K12="Excellent","5",IF(K12="Good","4",IF(K12="Average","3",IF(K12="Below Avg","2","1")))) -> 4 | V12: =IF(M12<3,"Fresher",IF(M12<7,"Mid Level","Senior")) -> Senior | W12: =IF(Table1[[#This Row],[Sales Status]]="Target Missed","Needs Improvement",IF(AND(Table1[[#This Row],[Sales Status]]="Achieved",W13="Excellent"), "Star", "Achiever" ) ) -> Achiever | X12: =IF(F12<30,"Gen-Z",IF(F12<40,"Millennial","Gen X")) -> Millennial | Y12: =IF(N12=0,"No Bonus",IF(N12<=8000,"Stanadard","Premium")) -> Premium
A13: E010 | B13: Meera Singh | C13: Finance | D13: =SUM(Employee_Sales_Data!M4:M53,">5",Employee_Sales_Data!H) -> #VALUE! | E13: Female | F13: 29 | G13: 2021-12-05 | H13: 85000 | I13: 0 | J13: 0 | K13: Good | L13: Active | M13: 4 | N13: 8500 | O13: =IF(N14>0,"Bonus Received","No Bonus") -> No Bonus | P13: =IF(Employee_Sales_Data!I13>Employee_Sales_Data!J13,"Target Achieved","Target Missed") -> Target Missed | Q13: =IF(H13>80000,"Senoir Pay Band","Junior Pay Band") -> Senoir Pay Band | R13: =IF(L13="Active","Current Employee","Ex-Employee") -> Current Employee | S13: =IF(F13>40,"Vetaran","Young Talent") -> Young Talent | T13: =IF(H13>=80000,"Grade A",IF(H13>50000,"Grade B","Grade C")) -> Grade A | U13: =IF(K13="Excellent","5",IF(K13="Good","4",IF(K13="Average","3",IF(K13="Below Avg","2","1")))) -> 4 | V13: =IF(M13<3,"Fresher",IF(M13<7,"Mid Level","Senior")) -> Mid Level | W13: =IF(Table1[[#This Row],[Sales Status]]="Target Missed","Needs Improvement",IF(AND(Table1[[#This Row],[Sales Status]]="Achieved",W14="Excellent"), "Star", "Achiever" ) ) -> Needs Improvement | X13: =IF(F13<30,"Gen-Z",IF(F13<40,"Millennial","Gen X")) -> Gen-Z | Y13: =IF(N13=0,"No Bonus",IF(N13<=8000,"Stanadard","Premium")) -> Premium
A14: E011 | B14: Suresh Rao | C14: Sales | D14: Bangalore | E14: Male | F14: 45 | G14: 2013-03-22 | H14: 55000 | I14: 142000 | J14: 180000 | K14: Below Avg | L14: Active | M14: 12 | N14: 0 | O14: =IF(N15>0,"Bonus Received","No Bonus") -> Bonus Received | P14: =IF(Employee_Sales_Data!I14>Employee_Sales_Data!J14,"Target Achieved","Target Missed") -> Target Missed | Q14: =IF(H14>80000,"Senoir Pay Band","Junior Pay Band") -> Junior Pay Band | R14: =IF(L14="Active","Current Employee","Ex-Employee") -> Current Employee | S14: =IF(F14>40,"Vetaran","Young Talent") -> Vetaran | T14: =IF(H14>=80000,"Grade A",IF(H14>50000,"Grade B","Grade C")) -> Grade B | U14: =IF(K14="Excellent","5",IF(K14="Good","4",IF(K14="Average","3",IF(K14="Below Avg","2","1")))) -> 2 | V14: =IF(M14<3,"Fresher",IF(M14<7,"Mid Level","Senior")) -> Senior | W14: =IF(Table1[[#This Row],[Sales Status]]="Target Missed","Needs Improvement",IF(AND(Table1[[#This Row],[Sales Status]]="Achieved",W15="Excellent"), "Star", "Achiever" ) ) -> Needs Improvement | X14: =IF(F14<30,"Gen-Z",IF(F14<40,"Millennial","Gen X")) -> Gen X | Y14: =IF(N14=0,"No Bonus",IF(N14<=8000,"Stanadard","Premium")) -> No Bonus
A15: E012 | B15: Kavitha Nair | C15: IT | D15: Chennai | E15: Female | F15: 32 | G15: 2019-07-17 | H15: 80000 | I15: 0 | J15: 0 | K15: Excellent | L15: Active | M15: 6 | N15: 9600 | O15: =IF(N16>0,"Bonus Received","No Bonus") -> Bonus Received | P15: =IF(Employee_Sales_Data!I15>Employee_Sales_Data!J15,"Target Achieved","Target Missed") -> Target Missed | Q15: =IF(H15>80000,"Senoir Pay Band","Junior Pay Band") -> Junior Pay Band | R15: =IF(L15="Active","Current Employee","Ex-Employee") -> Current Employee | S15: =IF(F15>40,"Vetaran","Young Talent") -> Young Talent | T15: =IF(H15>=80000,"Grade A",IF(H15>50000,"Grade B","Grade C")) -> Grade A | U15: =IF(K15="Excellent","5",IF(K15="Good","4",IF(K15="Average","3",IF(K15="Below Avg","2","1")))) -> 5 | V15: =IF(M15<3,"Fresher",IF(M15<7,"Mid Level","Senior")) -> Mid Level | W15: =IF(Table1[[#This Row],[Sales Status]]="Target Missed","Needs Improvement",IF(AND(Table1[[#This Row],[Sales Status]]="Achieved",W16="Excellent"), "Star", "Achiever" ) ) -> Needs Improvement | X15: =IF(F15<30,"Gen-Z",IF(F15<40,"Millennial","Gen X")) -> Millennial | Y15: =IF(N15=0,"No Bonus",IF(N15<=8000,"Stanadard","Premium")) -> Premium
A16: E013 | B16: Rahul Tiwari | C16: Sales | D16: Pune | E16: Male | F16: 24 | G16: 2023-01-09 | H16: 42000 | I16: 175000 | J16: 170000 | K16: Good | L16: Active | M16: 1 | N16: 7000 | O16: =IF(N17>0,"Bonus Received","No Bonus") -> Bonus Received | P16: =IF(Employee_Sales_Data!I16>Employee_Sales_Data!J16,"Target Achieved","Target Missed") -> Target Achieved | Q16: =IF(H16>80000,"Senoir Pay Band","Junior Pay Band") -> Junior Pay Band | R16: =IF(L16="Active","Current Employee","Ex-Employee") -> Current Employee | S16: =IF(F16>40,"Vetaran","Young Talent") -> Young Talent | T16: =IF(H16>=80000,"Grade A",IF(H16>50000,"Grade B","Grade C")) -> Grade C | U16: =IF(K16="Excellent","5",IF(K16="Good","4",IF(K16="Average","3",IF(K16="Below Avg","2","1")))) -> 4 | V16: =IF(M16<3,"Fresher",IF(M16<7,"Mid Level","Senior")) -> Fresher | W16: =IF(Table1[[#This Row],[Sales Status]]="Target Missed","Needs Improvement",IF(AND(Table1[[#This Row],[Sales Status]]="Achieved",W17="Excellent"), "Star", "Achiever" ) ) -> Achiever | X16: =IF(F16<30,"Gen-Z",IF(F16<40,"Millennial","Gen X")) -> Gen-Z | Y16: =IF(N16=0,"No Bonus",IF(N16<=8000,"Stanadard","Premium")) -> Stanadard
A17: E014 | B17: Pooja Gupta | C17: Finance | D17: Delhi | E17: Female | F17: 40 | G17: 2016-05-28 | H17: 95000 | I17: 0 | J17: 0 | K17: Excellent | L17: Active | M17: 9 | N17: 12000 | O17: =IF(N18>0,"Bonus Received","No Bonus") -> No Bonus | P17: =IF(Employee_Sales_Data!I17>Employee_Sales_Data!J17,"Target Achieved","Target Missed") -> Target Missed | Q17: =IF(H17>80000,"Senoir Pay Band","Junior Pay Band") -> Senoir Pay Band | R17: =IF(L17="Active","Current Employee","Ex-Employee") -> Current Employee | S17: =IF(F17>40,"Vetaran","Young Talent") -> Young Talent | T17: =IF(H17>=80000,"Grade A",IF(H17>50000,"Grade B","Grade C")) -> Grade A | U17: =IF(K17="Excellent","5",IF(K17="Good","4",IF(K17="Average","3",IF(K17="Below Avg","2","1")))) -> 5 | V17: =IF(M17<3,"Fresher",IF(M17<7,"Mid Level","Senior")) -> Senior | W17: =IF(Table1[[#This Row],[Sales Status]]="Target Missed","Needs Improvement",IF(AND(Table1[[#This Row],[Sales Status]]="Achieved",W18="Excellent"), "Star", "Achiever" ) ) -> Needs Improvement | X17: =IF(F17<30,"Gen-Z",IF(F17<40,"Millennial","Gen X")) -> Gen X | Y17: =IF(N17=0,"No Bonus",IF(N17<=8000,"Stanadard","Premium")) -> Premium
A18: E015 | B18: Nikhil Verma | C18: HR | D18: Mumbai | E18: Male | F18: 36 | G18: 2017-10-11 | H18: 65000 | I18: 0 | J18: 0 | K18: Good | L18: Inactive | M18: 8 | N18: 0 | O18: =IF(N19>0,"Bonus Received","No Bonus") -> Bonus Received | P18: =IF(Employee_Sales_Data!I18>Employee_Sales_Data!J18,"Target Achieved","Target Missed") -> Target Missed | Q18: =IF(H18>80000,"Senoir Pay Band","Junior Pay Band") -> Junior Pay Band | R18: =IF(L18="Active","Current Employee","Ex-Employee") -> Ex-Employee | S18: =IF(F18>40,"Vetaran","Young Talent") -> Young Talent | T18: =IF(H18>=80000,"Grade A",IF(H18>50000,"Grade B","Grade C")) -> Grade B | U18: =IF(K18="Excellent","5",IF(K18="Good","4",IF(K18="Average","3",IF(K18="Below Avg","2","1")))) -> 4 | V18: =IF(M18<3,"Fresher",IF(M18<7,"Mid Level","Senior")) -> Senior | W18: =IF(Table1[[#This Row],[Sales Status]]="Target Missed","Needs Improvement",IF(AND(Table1[[#This Row],[Sales Status]]="Achieved",W19="Excellent"), "Star", "Achiever" ) ) -> Needs Improvement | X18: =IF(F18<30,"Gen-Z",IF(F18<40,"Millennial","Gen X")) -> Millennial | Y18: =IF(N18=0,"No Bonus",IF(N18<=8000,"Stanadard","Premium")) -> No Bonus
A19: E016 | B19: Isha Chopra | C19: Sales | D19: Hyderabad | E19: Female | F19: 28 | G19: 2022-09-03 | H19: 49000 | I19: 198000 | J19: 190000 | K19: Good | L19: Active | M19: 2 | N19: 8500 | O19: =IF(N20>0,"Bonus Received","No Bonus") -> Bonus Received | P19: =IF(Employee_Sales_Data!I19>Employee_Sales_Data!J19,"Target Achieved","Target Missed") -> Target Achieved | Q19: =IF(H19>80000,"Senoir Pay Band","Junior Pay Band") -> Junior Pay Band | R19: =IF(L19="Active","Current Employee","Ex-Employee") -> Current Employee | S19: =IF(F19>40,"Vetaran","Young Talent") -> Young Talent | T19: =IF(H19>=80000,"Grade A",IF(H19>50000,"Grade B","Grade C")) -> Grade C | U19: =IF(K19="Excellent","5",IF(K19="Good","4",IF(K19="Average","3",IF(K19="Below Avg","2","1")))) -> 4 | V19: =IF(M19<3,"Fresher",IF(M19<7,"Mid Level","Senior")) -> Fresher | W19: =IF(Table1[[#This Row],[Sales Status]]="Target Missed","Needs Improvement",IF(AND(Table1[[#This Row],[Sales Status]]="Achieved",W20="Excellent"), "Star", "Achiever" ) ) -> Achiever | X19: =IF(F19<30,"Gen-Z",IF(F19<40,"Millennial","Gen X")) -> Gen-Z | Y19: =IF(N19=0,"No Bonus",IF(N19<=8000,"Stanadard","Premium")) -> Premium
A20: E017 | B20: Arjun Pillai | C20: IT | D20: Bangalore | E20: Male | F20: 31 | G20: 2020-06-16 | H20: 82000 | I20: 0 | J20: 0 | K20: Excellent | L20: Active | M20: 5 | N20: 9800 | O20: =IF(N21>0,"Bonus Received","No Bonus") -> No Bonus | P20: =IF(Employee_Sales_Data!I20>Employee_Sales_Data!J20,"Target Achieved","Target Missed") -> Target Missed | Q20: =IF(H20>80000,"Senoir Pay Band","Junior Pay Band") -> Senoir Pay Band | R20: =IF(L20="Active","Current Employee","Ex-Employee") -> Current Employee | S20: =IF(F20>40,"Vetaran","Young Talent") -> Young Talent | T20: =IF(H20>=80000,"Grade A",IF(H20>50000,"Grade B","Grade C")) -> Grade A | U20: =IF(K20="Excellent","5",IF(K20="Good","4",IF(K20="Average","3",IF(K20="Below Avg","2","1")))) -> 5 | V20: =IF(M20<3,"Fresher",IF(M20<7,"Mid Level","Senior")) -> Mid Level | W20: =IF(Table1[[#This Row],[Sales Status]]="Target Missed","Needs Improvement",IF(AND(Table1[[#This Row],[Sales Status]]="Achieved",W21="Excellent"), "Star", "Achiever" ) ) -> Needs Improvement | X20: =IF(F20<30,"Gen-Z",IF(F20<40,"Millennial","Gen X")) -> Millennial | Y20: =IF(N20=0,"No Bonus",IF(N20<=8000,"Stanadard","Premium")) -> Premium
A21: E018 | B21: Sunita Sharma | C21: Sales | D21: Mumbai | E21: Female | F21: 37 | G21: 2017-02-27 | H21: 60000 | I21: 155000 | J21: 180000 | K21: Average | L21: Active | M21: 8 | N21: 0 | O21: =IF(N22>0,"Bonus Received","No Bonus") -> Bonus Received | P21: =IF(Employee_Sales_Data!I21>Employee_Sales_Data!J21,"Target Achieved","Target Missed") -> Target Missed | Q21: =IF(H21>80000,"Senoir Pay Band","Junior Pay Band") -> Junior Pay Band | R21: =IF(L21="Active","Current Employee","Ex-Employee") -> Current Employee | S21: =IF(F21>40,"Vetaran","Young Talent") -> Young Talent | T21: =IF(H21>=80000,"Grade A",IF(H21>50000,"Grade B","Grade C")) -> Grade B | U21: =IF(K21="Excellent","5",IF(K21="Good","4",IF(K21="Average","3",IF(K21="Below Avg","2","1")))) -> 3 | V21: =IF(M21<3,"Fresher",IF(M21<7,"Mid Level","Senior")) -> Senior | W21: =IF(Table1[[#This Row],[Sales Status]]="Target Missed","Needs Improvement",IF(AND(Table1[[#This Row],[Sales Status]]="Achieved",W22="Excellent"), "Star", "Achiever" ) ) -> Needs Improvement | X21: =IF(F21<30,"Gen-Z",IF(F21<40,"Millennial","Gen X")) -> Millennial | Y21: =IF(N21=0,"No Bonus",IF(N21<=8000,"Stanadard","Premium")) -> No Bonus
A22: E019 | B22: Manish Agarwal | C22: Finance | D22: Pune | E22: Male | F22: 44 | G22: 2014-11-08 | H22: 98000 | I22: 0 | J22: 0 | K22: Good | L22: Active | M22: 11 | N22: 11000 | O22: =IF(N23>0,"Bonus Received","No Bonus") -> Bonus Received | P22: =IF(Employee_Sales_Data!I22>Employee_Sales_Data!J22,"Target Achieved","Target Missed") -> Target Missed | Q22: =IF(H22>80000,"Senoir Pay Band","Junior Pay Band") -> Senoir Pay Band | R22: =IF(L22="Active","Current Employee","Ex-Employee") -> Current Employee | S22: =IF(F22>40,"Vetaran","Young Talent") -> Vetaran | T22: =IF(H22>=80000,"Grade A",IF(H22>50000,"Grade B","Grade C")) -> Grade A | U22: =IF(K22="Excellent","5",IF(K22="Good","4",IF(K22="Average","3",IF(K22="Below Avg","2","1")))) -> 4 | V22: =IF(M22<3,"Fresher",IF(M22<7,"Mid Level","Senior")) -> Senior | W22: =IF(Table1[[#This Row],[Sales Status]]="Target Missed","Needs Improvement",IF(AND(Table1[[#This Row],[Sales Status]]="Achieved",W23="Excellent"), "Star", "Achiever" ) ) -> Needs Improvement | X22: =IF(F22<30,"Gen-Z",IF(F22<40,"Millennial","Gen X")) -> Gen X | Y22: =IF(N22=0,"No Bonus",IF(N22<=8000,"Stanadard","Premium")) -> Premium
A23: E020 | B23: Deepika Das | C23: Sales | D23: Chennai | E23: Female | F23: 25 | G23: 2023-04-18 | H23: 44000 | I23: 220000 | J23: 200000 | K23: Excellent | L23: Active | M23: 1 | N23: 10000 | O23: =IF(N24>0,"Bonus Received","No Bonus") -> Bonus Received | P23: =IF(Employee_Sales_Data!I23>Employee_Sales_Data!J23,"Target Achieved","Target Missed") -> Target Achieved | Q23: =IF(H23>80000,"Senoir Pay Band","Junior Pay Band") -> Junior Pay Band | R23: =IF(L23="Active","Current Employee","Ex-Employee") -> Current Employee | S23: =IF(F23>40,"Vetaran","Young Talent") -> Young Talent | T23: =IF(H23>=80000,"Grade A",IF(H23>50000,"Grade B","Grade C")) -> Grade C | U23: =IF(K23="Excellent","5",IF(K23="Good","4",IF(K23="Average","3",IF(K23="Below Avg","2","1")))) -> 5 | V23: =IF(M23<3,"Fresher",IF(M23<7,"Mid Level","Senior")) -> Fresher | W23: =IF(Table1[[#This Row],[Sales Status]]="Target Missed","Needs Improvement",IF(AND(Table1[[#This Row],[Sales Status]]="Achieved",W24="Excellent"), "Star", "Achiever" ) ) -> Achiever | X23: =IF(F23<30,"Gen-Z",IF(F23<40,"Millennial","Gen X")) -> Gen-Z | Y23: =IF(N23=0,"No Bonus",IF(N23<=8000,"Stanadard","Premium")) -> Premium
A24: E021 | B24: Sanjay Bhat | C24: HR | D24: Bangalore | E24: Male | F24: 50 | G24: 2011-01-15 | H24: 78000 | I24: 0 | J24: 0 | K24: Average | L24: Active | M24: 14 | N24: 7800 | O24: =IF(N25>0,"Bonus Received","No Bonus") -> No Bonus | P24: =IF(Employee_Sales_Data!I24>Employee_Sales_Data!J24,"Target Achieved","Target Missed") -> Target Missed | Q24: =IF(H24>80000,"Senoir Pay Band","Junior Pay Band") -> Junior Pay Band | R24: =IF(L24="Active","Current Employee","Ex-Employee") -> Current Employee | S24: =IF(F24>40,"Vetaran","Young Talent") -> Vetaran | T24: =IF(H24>=80000,"Grade A",IF(H24>50000,"Grade B","Grade C")) -> Grade B | U24: =IF(K24="Excellent","5",IF(K24="Good","4",IF(K24="Average","3",IF(K24="Below Avg","2","1")))) -> 3 | V24: =IF(M24<3,"Fresher",IF(M24<7,"Mid Level","Senior")) -> Senior | W24: =IF(Table1[[#This Row],[Sales Status]]="Target Missed","Needs Improvement",IF(AND(Table1[[#This Row],[Sales Status]]="Achieved",W25="Excellent"), "Star", "Achiever" ) ) -> Needs Improvement | X24: =IF(F24<30,"Gen-Z",IF(F24<40,"Millennial","Gen X")) -> Gen X | Y24: =IF(N24=0,"No Bonus",IF(N24<=8000,"Stanadard","Premium")) -> Stanadard
A25: E022 | B25: Lakshmi Menon | C25: Sales | D25: Delhi | E25: Female | F25: 30 | G25: 2020-08-22 | H25: 54000 | I25: 168000 | J25: 170000 | K25: Average | L25: Active | M25: 5 | N25: 0 | O25: =IF(N26>0,"Bonus Received","No Bonus") -> Bonus Received | P25: =IF(Employee_Sales_Data!I25>Employee_Sales_Data!J25,"Target Achieved","Target Missed") -> Target Missed | Q25: =IF(H25>80000,"Senoir Pay Band","Junior Pay Band") -> Junior Pay Band | R25: =IF(L25="Active","Current Employee","Ex-Employee") -> Current Employee | S25: =IF(F25>40,"Vetaran","Young Talent") -> Young Talent | T25: =IF(H25>=80000,"Grade A",IF(H25>50000,"Grade B","Grade C")) -> Grade B | U25: =IF(K25="Excellent","5",IF(K25="Good","4",IF(K25="Average","3",IF(K25="Below Avg","2","1")))) -> 3 | V25: =IF(M25<3,"Fresher",IF(M25<7,"Mid Level","Senior")) -> Mid Level | W25: =IF(Table1[[#This Row],[Sales Status]]="Target Missed","Needs Improvement",IF(AND(Table1[[#This Row],[Sales Status]]="Achieved",W26="Excellent"), "Star", "Achiever" ) ) -> Needs Improvement | X25: =IF(F25<30,"Gen-Z",IF(F25<40,"Millennial","Gen X")) -> Millennial | Y25: =IF(N25=0,"No Bonus",IF(N25<=8000,"Stanadard","Premium")) -> No Bonus
... A53: E050 | B53: Pallavi Nair | C53: Sales | D53: Chennai | E53: Female | F53: 28 | G53: 2022-01-25 | H53: 50000 | I53: 202000 | J53: 200000 | K53: Good | L53: Active | M53: 3 | N53: 8500 | O53: =IF(N54>0,"Bonus Received","No Bonus") -> No Bonus | P53: =IF(Employee_Sales_Data!I53>Employee_Sales_Data!J53,"Target Achieved","Target Missed") -> Target Achieved | Q53: =IF(H53>80000,"Senoir Pay Band","Junior Pay Band") -> Junior Pay Band | R53: =IF(L53="Active","Current Employee","Ex-Employee") -> Current Employee | S53: =IF(F53>40,"Vetaran","Young Talent") -> Young Talent | T53: =IF(H53>=80000,"Grade A",IF(H53>50000,"Grade B","Grade C")) -> Grade C | U53: =IF(K53="Excellent","5",IF(K53="Good","4",IF(K53="Average","3",IF(K53="Below Avg","2","1")))) -> 4 | V53: =IF(M53<3,"Fresher",IF(M53<7,"Mid Level","Senior")) -> Mid Level | W53: =IF(Table1[[#This Row],[Sales Status]]="Target Missed","Needs Improvement",IF(AND(Table1[[#This Row],[Sales Status]]="Achieved",W54="Excellent"), "Star", "Achiever" ) ) -> Achiever | X53: =IF(F53<30,"Gen-Z",IF(F53<40,"Millennial","Gen X")) -> Gen-Z | Y53: =IF(N53=0,"No Bonus",IF(N53<=8000,"Stanadard","Premium")) -> Premium

Sheet 50 Questions
A1: 📝 Excel Assignment — 50 Questions | TechVista Dataset
A2: Instructions: Write your answers in column D. Use the Employee_Sales_Data sheet as your dataset.
A3: # | B3: Function Used | C3: Question | D3: Your Answer | E3: Hint / Column Reference
A4: 1 | B4: AVERAGE | C4: What is the average Basic Salary of all 50 employees? | D4: =AVERAGE(Employee_Sales_Data!H4:H53) -> 66420 | E4: Col H (Basic Salary)
A5: 2 | B5: AVERAGE | C5: What is the average Age of all employees in the dataset? | D5: =AVERAGE(Employee_Sales_Data!F4:F53) -> 33.48 | E5: Col F (Age)
A6: 3 | B6: AVERAGE | C6: What is the average Sales Amount across all employees who have a non-zero sales figure? | D6: =AVERAGEIF(Employee_Sales_Data!I4:I53,">0") -> 179833.33 | E6: Col I (Sales Amount)
A7: 4 | B7: AVERAGE | C7: What is the average Bonus paid to all employees (include zeros)? | D7: =AVERAGE(Employee_Sales_Data!N4:N53) -> 6294.4 | E7: Col N (Bonus)
A8: 5 | B8: AVERAGE | C8: What is the average number of years of Experience across all employees? | D8: =AVERAGE(Employee_Sales_Data!M4:M53) -> 6 | E8: Col M (Experience)
A9: 6 | B9: SUM | C9: What is the total Basic Salary paid to all 50 employees? | D9: =SUM(Employee_Sales_Data!H4:H53) -> 3321000 | E9: Col H (Basic Salary)
A10: 7 | B10: SUM | C10: What is the combined total of all Sales Amounts in the dataset? | D10: =SUM(Employee_Sales_Data!I4:I53) -> 4316000 | E10: Col I (Sales Amount)
A11: 8 | B11: SUM | C11: What is the total Bonus amount distributed among all employees? | D11: =SUM(Employee_Sales_Data!N4:N53) -> 314720 | E11: Col N (Bonus)
A12: 9 | B12: SUM | C12: What is the total Sales Target set across all employees? | D12: =AVERAGE(Employee_Sales_Data!J4:J53) -> 88000 | E12: Col J (Sales Target)
A13: 10 | B13: SUM | C13: What is the sum of salaries of employees whose Experience is more than 5 years? (Use SUM only — manually filter visually) | D13: =SUMIF(Employee_Sales_Data!M4:M53,">5",Employee_Sales_Data!H4:H53) -> 2019000 | E13: Col H & Col M
A14: 11 | B14: COUNT | C14: How many employees have a numeric Bonus value? (Use COUNT) | D14: =COUNT(Employee_Sales_Data!N4:N53) -> 50 | E14: Col N (Bonus)
A15: 12 | B15: COUNT | C15: How many numeric entries are there in the Sales Amount column? | D15: =COUNT(Employee_Sales_Data!I4:I53) -> 50 | E15: Col I (Sales Amount)
A16: 13 | B16: COUNT | C16: How many employees have a numeric Age recorded? | D16: =AVERAGE(Employee_Sales_Data!F4:F53) -> 33.48 | E16: Col F (Age)
A17: 14 | B17: COUNT | C17: Use COUNT on the Date of Joining column — how many date entries exist? | D17: =COUNTA(Employee_Sales_Data!G4:G53) -> 50 | E17: Col G (Date of Joining)
A18: 15 | B18: COUNTA | C18: How many employees have their Performance Rating filled in? (Use COUNTA) | D18: =COUNTA(Employee_Sales_Data!K4:K53) -> 50 | E18: Col K (Performance Rating)
A19: 16 | B19: COUNTA | C19: How many entries are in the Employee Name column? (Use COUNTA) | D19: =COUNTA(Employee_Sales_Data!B4:B53) -> 50 | E19: Col B (Employee Name)
A20: 17 | B20: COUNTA | C20: How many employees have a City recorded? (Use COUNTA) | D20: =COUNTA(Employee_Sales_Data!D4:D53) -> 50 | E20: Col D (City)
A21: 18 | B21: COUNTBLANK | C21: How many employees have a blank Bonus value? (Use COUNTBLANK) | D21: =COUNTBLANK(Employee_Sales_Data!N4:N53) -> 0 | E21: Col N (Bonus)
A22: 19 | B22: COUNTBLANK | C22: How many cells are blank in the Sales Amount column? (Use COUNTBLANK) | D22: =COUNTBLANK(Employee_Sales_Data!I4:I53) -> 0 | E22: Col I (Sales Amount)
A23: 20 | B23: COUNTBLANK | C23: How many blank cells exist in the Sales Target column? (Use COUNTBLANK) | D23: =COUNTBLANK(Employee_Sales_Data!J4:J53) -> 0 | E23: Col J (Sales Target)
A24: 21 | B24: IF | C24: Create a new column: If an employee's Bonus > 0, write 'Bonus Received', else write 'No Bonus'. | E24: Col N (Bonus) → New Col
A25: 22 | B25: IF | C25: Create a column: If Sales Amount > Sales Target, write 'Target Achieved', else 'Target Missed'. | E25: Col I vs Col J
A26: 23 | B26: IF | C26: Create a column: If Basic Salary >= 80000, label as 'Senior Pay Band', else 'Junior Pay Band'. | E26: Col H (Basic Salary)
A27: 24 | B27: IF | C27: Create a column: If Status = 'Active', write 'Current Employee', else write 'Ex-Employee'. | E27: Col L (Status)
A28: 25 | B28: IF | C28: Create a column: If Age > 40, write 'Veteran', else write 'Young Talent'. | E28: Col F (Age)
A29: 26 | B29: Nested IF | C29: Create a Salary Grade column: <50000='Grade C', 50000–79999='Grade B', >=80000='Grade A'. | E29: Col H (Basic Salary)
A30: 27 | B30: Nested IF | C30: Create a Performance Score: 'Excellent'=5, 'Good'=4, 'Average'=3, 'Below Avg'=2. | E30: Col K (Performance Rating)
A31: 28 | B31: Nested IF | C31: Create an Experience Level: <3 yrs='Fresher', 3–7='Mid Level', >7='Senior'. | E31: Col M (Experience)
A32: 29 | B32: Nested IF | C32: Create a Sales Achievement Band: Achieved & Excellent='Star', Achieved & others='Achiever', Missed='Needs Improvement'. | E32: Col I, Col J, Col K
A33: 30 | B33: Nested IF | C33: Classify employees by Age: <30='Gen Z', 30–40='Millennial', >40='Gen X'. | E33: Col F (Age)
A34: 31 | B34: Nested IF | C34: Create a Bonus Tier: Bonus=0 → 'No Bonus', 1–8000 → 'Standard', >8000 → 'Premium'. | E34: Col N (Bonus)
A35: 32 | B35: COUNTIF | C35: How many employees are in the 'Sales' department? | D35: =COUNTIF(Employee_Sales_Data!C4:C53,"SALES") -> 24 | E35: Col C (Department)
A36: 33 | B36: COUNTIF | C36: How many employees are 'Active'? | D36: =COUNTIF(Employee_Sales_Data!L4:L53,"Active") -> 46 | E36: Col L (Status)
A37: 34 | B37: COUNTIF | C37: How many employees have a 'Good' Performance Rating? | D37: =COUNTIF(Employee_Sales_Data!K4:K53,"Good") -> 19 | E37: Col K (Performance Rating)
A38: 35 | B38: COUNTIF | C38: How many female employees are in the dataset? | D38: =COUNTIF(Employee_Sales_Data!E4:E53,"Female") -> 25 | E38: Col E (Gender)
A39: 36 | B39: COUNTIF | C39: How many employees are based in Mumbai? | D39: =COUNTIF(Employee_Sales_Data!D4:D53,"Mumbai") -> 10 | E39: Col D (City)
A40: 37 | B40: SUMIF | C40: What is the total salary paid to employees in the 'Finance' department? | D40: =SUMIF(Employee_Sales_Data!C4:C53,"Finance",Employee_Sales_Data!H4:H53) -> 867000 | E40: Col C & Col H
...

Sheet Formula Cheat Sheet
A1: 📖 Formula Quick Reference — Excel Functions
A2: Function | B2: Syntax | C2: Example on Dataset
A3: AVERAGE | B3: '=AVERAGE(range) | C3: '=AVERAGE(H4:H53)
A4: SUM | B4: '=SUM(range) | C4: '=SUM(H4:H53)
A5: COUNT | B5: '=COUNT(range) — counts numbers only | C5: '=COUNT(N4:N53)
A6: COUNTA | B6: '=COUNTA(range) — counts non-blank cells | C6: '=COUNTA(B4:B53)
A7: COUNTBLANK | B7: '=COUNTBLANK(range) — counts empty cells | C7: '=COUNTBLANK(N4:N53)
A8: IF | B8: '=IF(condition, "True value", "False value") | C8: '=IF(N4>0,"Bonus","No Bonus")
A9: Nested IF | B9: '=IF(cond1,"A",IF(cond2,"B","C")) | C9: '=IF(H4>=80000,"A",IF(H4>=50000,"B","C"))
A10: COUNTIF | B10: '=COUNTIF(range,"criteria") | C10: '=COUNTIF(C4:C53,"Sales")
A11: SUMIF | B11: '=SUMIF(range,"criteria",sum_range) | C11: '=SUMIF(C4:C53,"Finance",H4:H53)
A12: AVERAGEIF | B12: '=AVERAGEIF(range,"criteria",avg_range) | C12: '=AVERAGEIF(C4:C53,"IT",H4:H53)
A13: SUMIFS | B13: '=SUMIFS(sum_r,range1,"c1",range2,"c2") | C13: '=SUMIFS(H4:H53,E4:E53,"Female",C4:C53,"Sales")
A14: AVERAGEIFS | B14: '=AVERAGEIFS(avg_r,range1,"c1",range2,"c2") | C14: '=AVERAGEIFS(H4:H53,E4:E53,"Female",C4:C53,"Finance")
